<robot name="yamax">
  <material name="aluminium">
    <color rgba="0.5820 0.6445 0.6484 1.0"/>
  </material>
  <material name="mdf">
    <color rgba="0.8984 0.4922 0.1328 1.0"/>
  </material>

  <link name="head">
    <visual>
      <origin xyz="0 0 0" rpy="0 0 0" />
      <geometry>
        <box size="2.5 2 2" />
      </geometry>
      <material name="aluminium" />
    </visual>
  </link>

  <link name="body">
    <visual>
      <origin xyz="0 0 0" rpy="0 0 0" />
      <geometry>
        <box size="8 6 5" />
      </geometry>
      <material name="aluminium" />
    </visual>
  </link>

  <link name="arm_right_virtual" />

  <link name="arm_right_1">
    <visual>
      <origin xyz="0 -3 0" rpy="0 0 0" />
      <geometry>
        <box size="1 6 0.5" />
      </geometry>
      <material name="mdf" />
    </visual>
  </link>

  <link name="arm_right_2">
    <visual>
      <origin xyz="0 -2.5 0" rpy="0 0 0" />
      <geometry>
        <box size="1 5 0.5" />
      </geometry>
      <material name="mdf" />
    </visual>
  </link>

  <link name="arm_left_virtual" />

  <link name="arm_left_1">
    <visual>
      <origin xyz="0 -3 0" rpy="0 0 0" />
      <geometry>
        <box size="1 6 0.5" />
      </geometry>
      <material name="mdf" />
    </visual>
  </link>

  <link name="arm_left_2">
    <visual>
      <origin xyz="0 -2.5 0" rpy="0 0 0" />
      <geometry>
        <box size="1 5 0.5" />
      </geometry>
      <material name="mdf" />
    </visual>
  </link>

  <link name="stomach">
    <visual>
      <origin xyz="0 -2.5 0" rpy="0 0 0" />
      <geometry>
        <box size="3 5 3" />
      </geometry>
      <material name="aluminium" />
    </visual>
  </link>

  <link name="hip">
    <visual>
      <origin xyz="0 -0.5 0" rpy="0 0 0" />
      <geometry>
        <box size="9 1 5" />
      </geometry>
      <material name="mdf" />
    </visual>
  </link>

  <link name="leg_right_1_virtual" />

  <link name="leg_right_1">
    <visual>
      <origin xyz="0 -2 0" rpy="0 0 0" />
      <geometry>
        <box size="3 4 4" />
      </geometry>
      <material name="mdf" />
    </visual>
  </link>

  <link name="leg_right_2_virtual" />

  <link name="leg_right_2">
    <visual>
      <origin xyz="0 -2 0" rpy="0 0 0" />
      <geometry>
        <box size="3 4 4" />
      </geometry>
      <material name="mdf" />
    </visual>
  </link>

  <link name="leg_left_1_virtual" />

  <link name="leg_left_1">
    <visual>
      <origin xyz="0 -2 0" rpy="0 0 0" />
      <geometry>
        <box size="3 4 4" />
      </geometry>
      <material name="mdf" />
    </visual>
  </link>

  <link name="leg_left_2_virtual" />

  <link name="leg_left_2">
    <visual>
      <origin xyz="0 -2 0" rpy="0 0 0" />
      <geometry>
        <box size="3 4 4" />
      </geometry>
      <material name="mdf" />
    </visual>
  </link>

  <link name="foot_right">
    <visual>
      <origin xyz="0 -0.5 1" rpy="0 0 0" />
      <geometry>
        <box size="4 1 7" />
      </geometry>
      <material name="mdf" />
    </visual>
  </link>

  <link name="foot_left">
    <visual>
      <origin xyz="0 -0.5 1" rpy="0 0 0" />
      <geometry>
        <box size="4 1 7" />
      </geometry>
      <material name="mdf" />
    </visual>
  </link>


  <joint name="neck" type="revolute">
    <parent link="body"/>
    <child link="head"/>

    <origin xyz="0 4.5 0.5" rpy="0 0 0" />
    <axis xyz="0 1 0" />
    <limit lower="-1.5708" upper="1.5708" effort="10" velocity="10" />
  </joint>

  <joint name="shoulder_right_x" type="revolute">
    <parent link="body"/>
    <child link="arm_right_virtual"/>

    <origin xyz="-5 2 1" rpy="0 0 0" />
    <axis xyz="1 0 0" />
    <limit lower="-1.5708" upper="1.5708" effort="10" velocity="10" />
  </joint>

  <joint name="shoulder_right_z" type="revolute">
    <parent link="arm_right_virtual"/>
    <child link="arm_right_1"/>

    <origin xyz="0 0 0" rpy="0 0 0" />
    <axis xyz="0 0 1" />
    <limit lower="-1.5708" upper="1.5708" effort="10" velocity="10" />
  </joint>

  <joint name="shoulder_left_x" type="revolute">
    <parent link="body"/>
    <child link="arm_left_virtual"/>

    <origin xyz="5 2 1" rpy="0 0 0" />
    <axis xyz="1 0 0" />
    <limit lower="-1.5708" upper="1.5708" effort="10" velocity="10" />
  </joint>

  <joint name="shoulder_left_z" type="revolute">
    <parent link="arm_left_virtual"/>
    <child link="arm_left_1"/>

    <origin xyz="0 0 0" rpy="0 0 0" />
    <axis xyz="0 0 1" />
    <limit lower="-1.5708" upper="1.5708" effort="10" velocity="10" />
  </joint>

  <joint name="elbow_right" type="revolute">
    <parent link="arm_right_1"/>
    <child link="arm_right_2"/>

    <origin xyz="-1 -4 -1" rpy="0 -1.5708 0" />
    <axis xyz="0 0 1" />
    <limit lower="-1.5708" upper="1.5708" effort="10" velocity="10" />
  </joint>

  <joint name="elbow_left" type="revolute">
    <parent link="arm_left_1"/>
    <child link="arm_left_2"/>

    <origin xyz="1 -4 -1" rpy="0 -1.5708 0" />
    <axis xyz="0 0 1" />
    <limit lower="-1.5708" upper="1.5708" effort="10" velocity="10" />
  </joint>

  <joint name="backbone_1" type="revolute">
    <parent link="body"/>
    <child link="stomach"/>

    <origin xyz="0 0 1.5" rpy="0 0 0" />
    <axis xyz="0 0 1" />
    <limit lower="-1.5708" upper="1.5708" effort="10" velocity="10" />
  </joint>

  <joint name="backbone_2" type="revolute">
    <parent link="stomach"/>
    <child link="hip"/>

    <origin xyz="0 -5 0" rpy="0 0 0" />
    <axis xyz="1 0 0" />
    <limit lower="-1.5708" upper="1.5708" effort="10" velocity="10" />
  </joint>

  <joint name="hip_joint_right" type="revolute">
    <parent link="hip"/>
    <child link="leg_right_1"/>

    <origin xyz="-2.5 -2.5 0" rpy="0 0 0" />
    <axis xyz="0 0 1" />
    <limit lower="-1.5708" upper="1.5708" effort="10" velocity="10" />
  </joint>

  <joint name="hip_joint_left" type="revolute">
    <parent link="hip"/>
    <child link="leg_left_1"/>

    <origin xyz="2.5 -2.5 0" rpy="0 0 0" />
    <axis xyz="0 0 1" />
    <limit lower="-1.5708" upper="1.5708" effort="10" velocity="10" />
  </joint>

  <joint name="knee_right_x" type="revolute">
    <parent link="leg_right_1"/>
    <child link="leg_right_1_virtual"/>

    <origin xyz="0 -4.5 0" rpy="0 0 0" />
    <axis xyz="1 0 0" />
    <limit lower="-1.5708" upper="1.5708" effort="10" velocity="10" />
  </joint>

  <joint name="knee_right_z" type="revolute">
    <parent link="leg_right_1_virtual"/>
    <child link="leg_right_2"/>

    <origin xyz="0 0 0" rpy="0 0 0" />
    <axis xyz="0 0 1" />
    <limit lower="-1.5708" upper="1.5708" effort="10" velocity="10" />
  </joint>

  <joint name="knee_left_x" type="revolute">
    <parent link="leg_left_1"/>
    <child link="leg_left_1_virtual"/>

    <origin xyz="0 -4.5 0" rpy="0 0 0" />
    <axis xyz="1 0 0" />
    <limit lower="-1.5708" upper="1.5708" effort="10" velocity="10" />
  </joint>

  <joint name="knee_left_z" type="revolute">
    <parent link="leg_left_1_virtual"/>
    <child link="leg_left_2"/>

    <origin xyz="0 0 0" rpy="0 0 0" />
    <axis xyz="0 0 1" />
    <limit lower="-1.5708" upper="1.5708" effort="10" velocity="10" />
  </joint>

  <joint name="ankle_right_x" type="revolute">
    <parent link="leg_right_2"/>
    <child link="leg_right_2_virtual"/>

    <origin xyz="0 -4.5 0" rpy="0 0 0" />
    <axis xyz="1 0 0" />
    <limit lower="-1.5708" upper="1.5708" effort="10" velocity="10" />
  </joint>

  <joint name="ankle_right_z" type="revolute">
    <parent link="leg_right_2_virtual"/>
    <child link="foot_right"/>

    <origin xyz="0 0 0" rpy="0 0 0" />
    <axis xyz="0 0 1" />
    <limit lower="-1.5708" upper="1.5708" effort="10" velocity="10" />
  </joint>

  <joint name="ankle_left_x" type="revolute">
    <parent link="leg_left_2"/>
    <child link="leg_left_2_virtual"/>

    <origin xyz="0 -4.5 0" rpy="0 0 0" />
    <axis xyz="1 0 0" />
    <limit lower="-1.5708" upper="1.5708" effort="10" velocity="10" />
  </joint>

  <joint name="ankle_left_z" type="revolute">
    <parent link="leg_left_2_virtual"/>
    <child link="foot_left"/>

    <origin xyz="0 0 0" rpy="0 0 0" />
    <axis xyz="0 0 1" />
    <limit lower="-1.5708" upper="1.5708" effort="10" velocity="10" />
  </joint>
</robot>
