<?xml version="1.0"?>
<robot name="yamax">
  <material name="aluminium">
    <color rgba="0.5820 0.6445 0.6484 1.0"/>
  </material>
  <material name="mdf">
    <color rgba="0.8984 0.4922 0.1328 1.0"/>
  </material>

  <link name="head">
    <visual>
      <origin xyz="0 0 0" rpy="0 0 0" />
      <geometry>
        <box size="0.035 0.023 0.035" />
      </geometry>
      <material name="aluminium" />
    </visual>
    <collision>
      <origin xyz="0 0 0" rpy="0 0 0" />
      <geometry>
        <box size="0.035 0.023 0.035" />
      </geometry>
    </collision>
  </link>

  <link name="base_link">
    <visual>
      <origin xyz="0 0 0" rpy="0 0 0" />
      <geometry>
        <box size="0.11 0.094 0.05" />
      </geometry>
      <material name="aluminium" />
    </visual>
    <collision>
      <origin xyz="0 0 0" rpy="0 0 0" />
      <geometry>
        <box size="0.11 0.094 0.05" />
      </geometry>
    </collision>
  </link>

  <link name="arm_right_virtual" />

  <link name="arm_right_1">
    <visual>
      <origin xyz="0 -0.045 0" rpy="0 0 0" />
      <geometry>
        <box size="0.02 0.09 0.004" />
      </geometry>
      <material name="mdf" />
    </visual>
    <collision>
      <origin xyz="0 -0.045 0" rpy="0 0 0" />
      <geometry>
        <box size="0.02 0.09 0.004" />
      </geometry>
    </collision>
  </link>

  <link name="arm_right_2">
    <visual>
      <origin xyz="0 -0.03 0" rpy="0 0 0" />
      <geometry>
        <box size="0.02 0.06 0.004" />
      </geometry>
      <material name="mdf" />
    </visual>
    <collision>
      <origin xyz="0 -0.03 0" rpy="0 0 0" />
      <geometry>
        <box size="0.02 0.06 0.004" />
      </geometry>
    </collision>
  </link>

  <link name="arm_left_virtual" />

  <link name="arm_left_1">
    <visual>
      <origin xyz="0 -0.045 0" rpy="0 0 0" />
      <geometry>
        <box size="0.02 0.09 0.004" />
      </geometry>
      <material name="mdf" />
    </visual>
    <collision>
      <origin xyz="0 -0.045 0" rpy="0 0 0" />
      <geometry>
        <box size="0.02 0.09 0.004" />
      </geometry>
    </collision>
  </link>

  <link name="arm_left_2">
    <visual>
      <origin xyz="0 -0.03 0" rpy="0 0 0" />
      <geometry>
        <box size="0.02 0.06 0.004" />
      </geometry>
      <material name="mdf" />
    </visual>
    <collision>
      <origin xyz="0 -0.03 0" rpy="0 0 0" />
      <geometry>
        <box size="0.02 0.06 0.004" />
      </geometry>
    </collision>
  </link>

  <link name="stomach">
    <visual>
      <origin xyz="0 -0.035 0" rpy="0 0 0" />
      <geometry>
        <box size="0.053 0.070 0.054" />
      </geometry>
      <material name="aluminium" />
    </visual>
    <collision>
      <origin xyz="0 -0.035 0" rpy="0 0 0" />
      <geometry>
        <box size="0.053 0.070 0.054" />
      </geometry>
    </collision>
  </link>

  <link name="hip">
    <visual>
      <origin xyz="0 -0.0025 0" rpy="0 0 0" />
      <geometry>
        <box size="0.11 0.004 0.05" />
      </geometry>
      <material name="mdf" />
    </visual>
    <collision>
      <origin xyz="0 -0.0025 0" rpy="0 0 0" />
      <geometry>
        <box size="0.11 0.004 0.05" />
      </geometry>
    </collision>
  </link>

  <link name="hip_right">
    <visual>
      <origin xyz="0 -0.0225 0" rpy="0 0 0" />
      <geometry>
        <box size="0.045 0.045 0.055" />
      </geometry>
      <material name="mdf" />
    </visual>
    <collision>
      <origin xyz="0 -0.0225 0" rpy="0 0 0" />
      <geometry>
        <box size="0.045 0.045 0.055" />
      </geometry>
    </collision>
  </link>

  <link name="leg_right_1">
    <visual>
      <origin xyz="0 -0.0115 0" rpy="0 0 0" />
      <geometry>
        <box size="0.045 0.023 0.045" />
      </geometry>
      <material name="mdf" />
    </visual>
    <collision>
      <origin xyz="0 -0.0115 0" rpy="0 0 0" />
      <geometry>
        <box size="0.045 0.023 0.045" />
      </geometry>
    </collision>
  </link>

  <link name="leg_right_2">
    <visual>
      <origin xyz="0 -0.0175 0" rpy="0 0 0" />
      <geometry>
        <box size="0.060 0.035 0.022" />
      </geometry>
      <material name="mdf" />
    </visual>
    <collision>
      <origin xyz="0 -0.0175 0" rpy="0 0 0" />
      <geometry>
        <box size="0.060 0.035 0.022" />
      </geometry>
    </collision>
  </link>

  <link name="leg_right_3">
    <visual>
      <origin xyz="0 -0.021 0" rpy="0 0 0" />
      <geometry>
        <box size="0.045 0.042 0.055" />
      </geometry>
      <material name="mdf" />
    </visual>
    <collision>
      <origin xyz="0 -0.021 0" rpy="0 0 0" />
      <geometry>
        <box size="0.045 0.042 0.055" />
      </geometry>
    </collision>
  </link>

  <link name="hip_left">
    <visual>
      <origin xyz="0 -0.0225 0" rpy="0 0 0" />
      <geometry>
        <box size="0.045 0.045 0.055" />
      </geometry>
      <material name="mdf" />
    </visual>
    <collision>
      <origin xyz="0 -0.0225 0" rpy="0 0 0" />
      <geometry>
        <box size="0.045 0.045 0.055" />
      </geometry>
    </collision>
  </link>

  <link name="leg_left_1">
    <visual>
      <origin xyz="0 -0.0115 0" rpy="0 0 0" />
      <geometry>
        <box size="0.045 0.023 0.045" />
      </geometry>
      <material name="mdf" />
    </visual>
    <collision>
      <origin xyz="0 -0.0115 0" rpy="0 0 0" />
      <geometry>
        <box size="0.045 0.023 0.045" />
      </geometry>
    </collision>
  </link>

  <link name="leg_left_2">
    <visual>
      <origin xyz="0 -0.0175 0" rpy="0 0 0" />
      <geometry>
        <box size="0.060 0.035 0.022" />
      </geometry>
      <material name="mdf" />
    </visual>
    <collision>
      <origin xyz="0 -0.0175 0" rpy="0 0 0" />
      <geometry>
        <box size="0.060 0.035 0.022" />
      </geometry>
    </collision>
  </link>

  <link name="leg_left_3">
    <visual>
      <origin xyz="0 -0.021 0" rpy="0 0 0" />
      <geometry>
        <box size="0.045 0.042 0.055" />
      </geometry>
      <material name="mdf" />
    </visual>
    <collision>
      <origin xyz="0 -0.021 0" rpy="0 0 0" />
      <geometry>
        <box size="0.045 0.042 0.055" />
      </geometry>
    </collision>
  </link>

  <link name="foot_right">
    <visual>
      <origin xyz="0 -0.0025 0" rpy="0 0 0" />
      <geometry>
        <box size="0.060 0.004 0.090" />
      </geometry>
      <material name="mdf" />
    </visual>
    <collision>
      <origin xyz="0 -0.0025 0" rpy="0 0 0" />
      <geometry>
        <box size="0.060 0.004 0.090" />
      </geometry>
    </collision>
  </link>

  <link name="foot_left">
    <visual>
      <origin xyz="0 -0.0025 0" rpy="0 0 0" />
      <geometry>
        <box size="0.060 0.004 0.090" />
      </geometry>
      <material name="mdf" />
    </visual>
    <collision>
      <origin xyz="0 -0.0025 0" rpy="0 0 0" />
      <geometry>
        <box size="0.060 0.004 0.090" />
      </geometry>
    </collision>
  </link>


  <joint name="neck" type="revolute">
    <parent link="base_link"/>
    <child link="head"/>

    <origin xyz="0 0.070 -0.004" rpy="0 0 0" />
    <axis xyz="0 1 0" />
    <limit lower="-1.5708" upper="1.5708" effort="10" velocity="10" />
  </joint>

  <joint name="shoulder_right_x" type="revolute">
    <parent link="base_link"/>
    <child link="arm_right_virtual"/>

    <origin xyz="-0.075 0.040 0.025" rpy="0 0 0" />
    <axis xyz="1 0 0" />
    <limit lower="-1.5708" upper="1.5708" effort="10" velocity="10" />
  </joint>

  <joint name="shoulder_right_z" type="revolute">
    <parent link="arm_right_virtual"/>
    <child link="arm_right_1"/>

    <origin xyz="0 0 0" rpy="0 0 0" />
    <axis xyz="0 0 1" />
    <limit lower="-1.5708" upper="1.5708" effort="10" velocity="10" />
  </joint>

  <joint name="shoulder_left_x" type="revolute">
    <parent link="base_link"/>
    <child link="arm_left_virtual"/>

    <origin xyz="0.075 0.040 0.025" rpy="0 0 0" />
    <axis xyz="1 0 0" />
    <limit lower="-1.5708" upper="1.5708" effort="10" velocity="10" />
  </joint>

  <joint name="shoulder_left_z" type="revolute">
    <parent link="arm_left_virtual"/>
    <child link="arm_left_1"/>

    <origin xyz="0 0 0" rpy="0 0 0" />
    <axis xyz="0 0 1" />
    <limit lower="-1.5708" upper="1.5708" effort="10" velocity="10" />
  </joint>

  <joint name="elbow_right" type="revolute">
    <parent link="arm_right_1"/>
    <child link="arm_right_2"/>

    <origin xyz="-0.020 -0.080 -0.010" rpy="0 -1.5708 0" />
    <axis xyz="0 0 1" />
    <limit lower="-1.5708" upper="1.5708" effort="10" velocity="10" />
  </joint>

  <joint name="elbow_left" type="revolute">
    <parent link="arm_left_1"/>
    <child link="arm_left_2"/>

    <origin xyz="0.020 -0.080 -0.010" rpy="0 -1.5708 0" />
    <axis xyz="0 0 1" />
    <limit lower="-1.5708" upper="1.5708" effort="10" velocity="10" />
  </joint>

  <joint name="backbone_1" type="revolute">
    <parent link="base_link"/>
    <child link="stomach"/>

    <origin xyz="0 -0.020 0.004" rpy="0 0 0" />
    <axis xyz="0 0 1" />
    <limit lower="-1.5708" upper="1.5708" effort="10" velocity="10" />
  </joint>

  <joint name="backbone_2" type="revolute">
    <parent link="stomach"/>
    <child link="hip"/>

    <origin xyz="0 -0.065 0" rpy="0 0 0" />
    <axis xyz="1 0 0" />
    <limit lower="-1.5708" upper="1.5708" effort="10" velocity="10" />
  </joint>

  <joint name="hip_joint_right_z" type="revolute">
    <parent link="hip"/>
    <child link="hip_right"/>

    <origin xyz="-0.035 -0.017 0" rpy="0 0 0" />
    <axis xyz="0 0 1" />
    <limit lower="-1.5708" upper="1.5708" effort="10" velocity="10" />
  </joint>

  <joint name="hip_joint_right_x" type="revolute">
    <parent link="hip_right"/>
    <child link="leg_right_1"/>

    <origin xyz="0 -0.050 0.010" rpy="0 0 0" />
    <axis xyz="1 0 0" />
    <limit lower="-1.5708" upper="1.5708" effort="10" velocity="10" />
  </joint>

  <joint name="hip_joint_left_z" type="revolute">
    <parent link="hip"/>
    <child link="hip_left"/>

    <origin xyz="0.035 -0.017 0" rpy="0 0 0" />
    <axis xyz="0 0 1" />
    <limit lower="-1.5708" upper="1.5708" effort="10" velocity="10" />
  </joint>

  <joint name="hip_joint_left_x" type="revolute">
    <parent link="hip_left"/>
    <child link="leg_left_1"/>

    <origin xyz="0 -0.050 0.010" rpy="0 0 0" />
    <axis xyz="1 0 0" />
    <limit lower="-1.5708" upper="1.5708" effort="10" velocity="10" />
  </joint>

  <joint name="knee_right" type="revolute">
    <parent link="leg_right_1"/>
    <child link="leg_right_2"/>

    <origin xyz="0 -0.010 -0.010" rpy="0 0 0" />
    <axis xyz="1 0 0" />
    <limit lower="-1.5708" upper="1.5708" effort="10" velocity="10" />
  </joint>

  <joint name="knee_left" type="revolute">
    <parent link="leg_left_1"/>
    <child link="leg_left_2"/>

    <origin xyz="0 -0.010 -0.010" rpy="0 0 0" />
    <axis xyz="1 0 0" />
    <limit lower="-1.5708" upper="1.5708" effort="10" velocity="10" />
  </joint>

  <joint name="ankle_1_right" type="revolute">
    <parent link="leg_right_2"/>
    <child link="leg_right_3"/>

    <origin xyz="0 -0.020 0" rpy="0 0 0" />
    <axis xyz="1 0 0" />
    <limit lower="-1.5708" upper="1.5708" effort="10" velocity="10" />
  </joint>

  <joint name="ankle_1_left" type="revolute">
    <parent link="leg_left_2"/>
    <child link="leg_left_3"/>

    <origin xyz="0 -0.020 0" rpy="0 0 0" />
    <axis xyz="1 0 0" />
    <limit lower="-1.5708" upper="1.5708" effort="10" velocity="10" />
  </joint>

  <joint name="ankle_2_right" type="revolute">
    <parent link="leg_right_3"/>
    <child link="foot_right"/>

    <origin xyz="0 -0.055 0.01" rpy="0 0 0" />
    <axis xyz="0 0 1" />
    <limit lower="-1.5708" upper="1.5708" effort="10" velocity="10" />
  </joint>

  <joint name="ankle_2_left" type="revolute">
    <parent link="leg_left_3"/>
    <child link="foot_left"/>

    <origin xyz="0 -0.055 0.01" rpy="0 0 0" />
    <axis xyz="0 0 1" />
    <limit lower="-1.5708" upper="1.5708" effort="10" velocity="10" />
  </joint>
</robot>
